2024-08-20 10:05:36,037 INFO    StreamThr :33344 [internal.py:wandb_internal():85] W&B internal server running at pid: 33344, started at: 2024-08-20 10:05:36.036144
2024-08-20 10:05:36,039 DEBUG   HandlerThread:33344 [handler.py:handle_request():158] handle_request: status
2024-08-20 10:05:36,046 INFO    WriterThread:33344 [datastore.py:open_for_write():87] open: D:\FG-SSL-main\wandb\run-20240820_100536-oj60cqlb\run-oj60cqlb.wandb
2024-08-20 10:05:36,047 DEBUG   SenderThread:33344 [sender.py:send():391] send: header
2024-08-20 10:05:36,048 DEBUG   SenderThread:33344 [sender.py:send():391] send: run
2024-08-20 10:05:37,277 ERROR   SenderThread:33344 [internal_api.py:execute():349] 403 response executing GraphQL.
2024-08-20 10:05:37,279 ERROR   SenderThread:33344 [internal_api.py:execute():350] {"errors":[{"message":"permission denied","path":["upsertBucket"],"extensions":{"code":"PERMISSION_ERROR"}}],"data":{"upsertBucket":null}}
2024-08-20 10:05:37,283 ERROR   SenderThread:33344 [sender.py:send_run():1021] It appears that you do not have permission to access the requested resource. Please reach out to the project owner to grant you access. If you have the correct permissions, verify that there are no issues with your networking setup.(Error 403: Forbidden)
Traceback (most recent call last):
  File "D:\666\envs\pytorch\lib\site-packages\wandb\sdk\lib\retry.py", line 131, in __call__
    result = self._call_fn(*args, **kwargs)
  File "D:\666\envs\pytorch\lib\site-packages\wandb\sdk\internal\internal_api.py", line 345, in execute
    return self.client.execute(*args, **kwargs)  # type: ignore
  File "D:\666\envs\pytorch\lib\site-packages\wandb\vendor\gql-0.2.0\wandb_gql\client.py", line 52, in execute
    result = self._get_result(document, *args, **kwargs)
  File "D:\666\envs\pytorch\lib\site-packages\wandb\vendor\gql-0.2.0\wandb_gql\client.py", line 60, in _get_result
    return self.transport.execute(document, *args, **kwargs)
  File "D:\666\envs\pytorch\lib\site-packages\wandb\sdk\lib\gql_request.py", line 59, in execute
    request.raise_for_status()
  File "D:\666\envs\pytorch\lib\site-packages\requests\models.py", line 1021, in raise_for_status
    raise HTTPError(http_error_msg, response=self)
requests.exceptions.HTTPError: 403 Client Error: Forbidden for url: https://api.wandb.ai/graphql

During handling of the above exception, another exception occurred:

Traceback (most recent call last):
  File "D:\666\envs\pytorch\lib\site-packages\wandb\sdk\internal\sender.py", line 1019, in send_run
    server_run = self._init_run(run, config_value_dict)
  File "D:\666\envs\pytorch\lib\site-packages\wandb\sdk\internal\sender.py", line 1091, in _init_run
    server_run, inserted, server_messages = self._api.upsert_run(
  File "D:\666\envs\pytorch\lib\site-packages\wandb\apis\normalize.py", line 73, in wrapper
    raise err
  File "D:\666\envs\pytorch\lib\site-packages\wandb\apis\normalize.py", line 41, in wrapper
    return func(*args, **kwargs)
  File "D:\666\envs\pytorch\lib\site-packages\wandb\sdk\internal\internal_api.py", line 2224, in upsert_run
    response = self.gql(
  File "D:\666\envs\pytorch\lib\site-packages\wandb\sdk\internal\internal_api.py", line 317, in gql
    ret = self._retry_gql(
  File "D:\666\envs\pytorch\lib\site-packages\wandb\sdk\lib\retry.py", line 147, in __call__
    retry_timedelta_triggered = check_retry_fn(e)
  File "D:\666\envs\pytorch\lib\site-packages\wandb\util.py", line 968, in check_retry_fn
    return fallback_retry_fn(e)
  File "D:\666\envs\pytorch\lib\site-packages\wandb\util.py", line 910, in no_retry_auth
    raise CommError(
wandb.errors.CommError: It appears that you do not have permission to access the requested resource. Please reach out to the project owner to grant you access. If you have the correct permissions, verify that there are no issues with your networking setup.(Error 403: Forbidden)
2024-08-20 10:05:39,128 DEBUG   HandlerThread:33344 [handler.py:handle_request():158] handle_request: shutdown
2024-08-20 10:05:39,128 INFO    HandlerThread:33344 [handler.py:finish():880] shutting down handler
2024-08-20 10:05:39,296 INFO    SenderThread:33344 [sender.py:finish():1631] shutting down sender
2024-08-20 10:05:40,075 INFO    WriterThread:33344 [datastore.py:close():296] close: D:\FG-SSL-main\wandb\run-20240820_100536-oj60cqlb\run-oj60cqlb.wandb
